Workbook

Sheet Historiske finansielle tall
B2: TOMRA ASA
B4: Aksjekurs | C4: 104.8
B5: Antall aksjer | C5: 296040156
B6: Markedsverdi (NOK) | C6: =C4*C5 -> 3.1025008e+10
B9: EUR million | C9: 2018 | D9: 2019 | E9: 2020 | F9: 2021 | G9: 2022 | H9: 2023 | I9: 2024 | J9: 2025
B10: Operating revenues | C10: 895.4 | D10: 948.2 | E10: 927.1 | F10: 1074.3 | G10: 1204.8 | H10: 1288 | I10: 1348 | J10: 1318
B11: EBITA | C11: 130.5 | D11: 140 | E11: 141.9 | F11: 174.3 | G11: 160.4 | H11: 119 | I11: 176 | J11: 174
B12: Operating profit (EBIT) | C12: 112.3 | D12: 119.2 | E12: 121.2 | F12: 153 | G12: 143 | H12: 101 | I12: 156 | J12: 148
B13: Profit before taxes | C13: 107.6 | D13: 114.4 | E13: 99.1 | F13: 150.2 | G13: 138.2 | H13: 85 | I13: 131 | J13: 130
B14: Net cash flow from operating activities | C14: 106.8 | D14: 133.3 | E14: 159.5 | F14: 175 | G14: 114 | H14: 136.8 | I14: 235.5 | J14: 170.9
B15: Capital expenditure | C15: 76.9 | D15: 64.6 | E15: 56.9 | F15: 58.3 | G15: 82.3 | H15: 92.9 | I15: 118.3 | J15: 131.5
B16: Free cash flow | C16: =C14-C15 -> 29.9 | D16: =D14-D15 -> 68.7 | E16: =E14-E15 -> 102.6 | F16: =F14-F15 -> 116.7 | G16: =G14-G15 -> 31.7 | H16: =H14-H15 -> 43.9 | I16: =I14-I15 -> 117.2 | J16: =J14-J15 -> 39.4
B17: FCF conversion | C17: =C16/C11 -> 0.22911877 | D17: =D16/D11 -> 0.49071429 | E17: =E16/E11 -> 0.7230444 | F17: =F16/F11 -> 0.66953528 | G17: =G16/G11 -> 0.19763092 | H17: =H16/H11 -> 0.36890756 | I17: =I16/I11 -> 0.66590909 | J17: =J16/J11 -> 0.22643678
B19: ROCE | C19: n/a | D19: n/a | E19: 0.19 | F19: 0.229 | G19: 0.193 | H19: 0.173 | I19: 0.184 | J19: 0.152
B20: ROE | C20: 0.153 | D20: 0.162 | E20: 0.148 | F20: 0.193 | G20: 0.168 | H20: 0.099 | I20: 0.157 | J20: 0.157
B23: Revenue | C23: =C10 -> 895.4 | D23: =D10 -> 948.2 | E23: =E10 -> 927.1 | F23: =F10 -> 1074.3 | G23: =G10 -> 1204.8 | H23: =H10 -> 1288 | I23: =I10 -> 1348 | J23: =J10 -> 1318
B24: Cost of goods sold | C24: 511.8 | D24: 533.7 | E24: 519.9 | F24: 602.7 | G24: 705.5 | H24: 739.7 | I24: 764 | J24: 733
B25: Gross contribution | C25: =C23-C24 -> 383.6 | D25: =D23-D24 -> 414.5 | E25: =E23-E24 -> 407.2 | F25: =F23-F24 -> 471.6 | G25: =G23-G24 -> 499.3 | H25: =H23-H24 -> 548.3 | I25: =I23-I24 -> 584 | J25: =J23-J24 -> 585
B26: Gross margin | C26: =C25/C23 -> 0.42841188 | D26: =D25/D23 -> 0.43714406 | E26: =E25/E23 -> 0.43921907 | F26: =F25/F23 -> 0.43898352 | G26: =G25/G23 -> 0.41442563 | H26: =H25/H23 -> 0.42569876 | I26: =I25/I23 -> 0.43323442 | J26: =J25/J23 -> 0.44385432
B29: Inventory | C29: 145.5 | D29: 161.8 | E29: 142.5 | F29: 188.6 | G29: 225.4 | H29: 237.4 | I29: 225.5 | J29: 254.6
B30: Receivables | C30: 191.6 | D30: 203 | E30: 221.7 | F30: 267.4 | G30: 327.8 | H30: 361.1 | I30: 373.7 | J30: 400.6
B31: Contract assets | C31: 41 | D31: 29 | E31: 2.6 | F31: 3.8 | G31: 10.8 | H31: 9.7 | I31: 19.6 | J31: 16.5
B32: Contract liabilities | C32: 59.2 | D32: 49.9 | E32: 46.5 | F32: 57.8 | G32: 77.9 | H32: 64.8 | I32: 89.4 | J32: 83.2
B33: Trade payables | C33: 63.2 | D33: 50.9 | E33: 52.8 | F33: 64.5 | G33: 62.5 | H33: 73.5 | I33: 61.4 | J33: 75
B34: Other current liabilities | C34: 96.5 | D34: 92.8 | E34: 90.1 | F34: 121.2 | G34: 127.2 | H34: 202.3 | I34: 206 | J34: 184.8
B35: Working capital | C35: =C29+C30+C31-C32-C33-C34 -> 159.2 | D35: =D29+D30+D31-D32-D33-D34 -> 200.2 | E35: =E29+E30+E31-E32-E33-E34 -> 177.4 | F35: =F29+F30+F31-F32-F33-F34 -> 216.3 | G35: =G29+G30+G31-G32-G33-G34 -> 296.4 | H35: =H29+H30+H31-H32-H33-H34 -> 267.6 | I35: =I29+I30+I31-I32-I33-I34 -> 262 | J35: =J29+J30+J31-J32-J33-J34 -> 328.7
B36: Working capital relative to revenue | C36: =C35/C23 -> 0.17779763 | D36: =D35/D23 -> 0.21113689 | E36: =E35/E23 -> 0.19134937 | F36: =F35/F23 -> 0.20134041 | G36: =G35/G23 -> 0.24601594 | H36: =H35/H23 -> 0.20776398 | I36: =I35/I23 -> 0.19436202 | J36: =J35/J23 -> 0.24939302
C39: =D9 -> 2019 | D39: =E9 -> 2020 | E39: =F9 -> 2021 | F39: =G9 -> 2022 | G39: =H9 -> 2023 | H39: =I9 -> 2024 | I39: =J9 -> 2025
B40: Omsetning | C40: =D23 -> 948.2 | D40: =E23 -> 927.1 | E40: =F23 -> 1074.3 | F40: =G23 -> 1204.8 | G40: =H23 -> 1288 | H40: =I23 -> 1348 | I40: =J23 -> 1318
B41: Bruttomargin | C41: =D26 -> 0.43714406 | D41: =E26 -> 0.43921907 | E41: =F26 -> 0.43898352 | F41: =G26 -> 0.41442563 | G41: =H26 -> 0.42569876 | H41: =I26 -> 0.43323442 | I41: =J26 -> 0.44385432
C53: 2019 | D53: 2020 | E53: 2021 | F53: 2022 | G53: 2023 | H53: 2024 | I53: 2025
B54: Justert EBITA | C54: =D11 -> 140 | D54: =E11 -> 141.9 | E54: =F11 -> 174.3 | F54: =G11 -> 160.4 | G54: =H11 -> 119 | H54: =I11 -> 176 | I54: =J11 -> 174
B55: EBITA-margin | C55: =D11/D10 -> 0.14764818 | D55: =E11/E10 -> 0.15305792 | E55: =F11/F10 -> 0.16224518 | F55: =G11/G10 -> 0.13313413 | G55: =H11/H10 -> 0.092391304 | H55: =I11/I10 -> 0.1305638 | I55: =J11/J10 -> 0.13201821
B67: ´2018-2020 er rapportert i MNOK så har omgjort for å kunne sammenligne´
C68: 2019 | D68: 2020 | E68: 2021 | F68: 2022 | G68: 2023 | H68: 2024 | I68: 2025
B69: Arbeidskapital som andel av omsetning | C69: =D36 -> 0.21113689 | D69: =E36 -> 0.19134937 | E69: =F36 -> 0.20134041 | F69: =G36 -> 0.24601594 | G69: =H36 -> 0.20776398 | H69: =I36 -> 0.19436202 | I69: =J36 -> 0.24939302
B71: År | C71: 2020 | D71: 2021 | E71: 2022 | F71: 2023 | G71: 2024 | H71: 2025
B72: EBITA brukt i beregningen | C72: =E11 -> 141.9 | D72: =F11 -> 174.3 | E72: =G11 -> 160.4 | F72: 162 | G72: 181 | H72: 171
B73: ROCE brukt i beregningen | C73: =E19 -> 0.19 | D73: =F19 -> 0.229 | E73: =G19 -> 0.193 | F73: =H19 -> 0.173 | G73: =I19 -> 0.184 | H73: =J19 -> 0.152
B74: EBIT brukt i beregningen | C74: =E12 -> 121.2 | D74: =F12 -> 153 | E74: =G12 -> 143 | F74: 143 | G74: 162 | H74: 146
...

Sheet WACC
B2: WACC-Beregning
B4: Risikofri rente | C4: 0.0446 | E4: Kilde: https://tradingeconomics.com/norway/government-bond-yield
B5: Markedets risikopremie | C5: 0.0525
B6: Beta | C6: =(SLOPE(D40:D1295,F40:F1295))*2/3+1/3 -> 0.91486792
B7: Landrisikopremie | C7: 0
B8: Kostnad på egenkapital | C8: =C4+C6*C5+C7 -> 0.092630566
B11: Kostnad på gjeld f/skatt | C11: 0.055
B12: Skattesats | C12: ='Forecast Base'!C57 -> 0.245
B13: Kostnad på gjeld etter skatt | C13: =C11*(1-C12) -> 0.041525
B16: Aksjekurs i NOK | C16: ='Historiske finansielle tall'!C4 -> 104.8
B17: Antall aksjer | C17: ='Historiske finansielle tall'!C5 -> 296040156
B18: Markedsverdi egenkapital, NOK mill | C18: =(C16*C17)/1000000 -> 31025.008
B19: Netto rentebærende gjeld, NOK mill | C19: =DCF!C21*DCF!C6 -> 5361.72
B20: Leasinggjeld, NOK mill | C20: =DCF!C22*DCF!C6 -> 1627.08
B21: Gjeld brukt i WACC | C21: =C19+C20 -> 6988.8
B22: Totalkapital | C22: =C18+C21 -> 38013.808
B23: Egenkapitalvekt | C23: =C18/C22 -> 0.81615102
B24: Gjeldsvekt | C24: =C21/C22 -> 0.18384898
B26: Kontroll | C26: =C23+C24 -> 1
B28: Egenkapitalvekt | C28: =C23 -> 0.81615102
B29: Kostnad på egenkapital | C29: =C8 -> 0.092630566
B30: Gjeldsvekt | C30: =C24 -> 0.18384898
B31: Gjeldskostnad etter skatt | C31: =C13 -> 0.041525
B32: WACC | C32: =C28*C29+C30*C31 -> 0.08323486
B34: *Alle data hentet 31.juli 2026*
B37: UTREGNING BETA
B38: Dato ukeslutt | C38: TOMRA Kurs | D38: Endring | E38: OSEBX kurs | F38: Endring
B39: 44414 | C39: 255.8 | E39: 1145.55
B40: 44421 | C40: 258.4 | D40: =(C40-C39)/C39 -> 0.010164191 | E40: 1159 | F40: =(E40-E39)/E39 -> 0.011741085
B41: 44428 | C41: 260.7 | D41: =(C41-C40)/C40 -> 0.0089009288 | E41: 1133.18 | F41: =(E41-E40)/E40 -> -0.022277826
B42: 44435 | C42: 262.8 | D42: =(C42-C41)/C41 -> 0.0080552359 | E42: 1164.58 | F42: =(E42-E41)/E41 -> 0.027709631
B43: 44442 | C43: 262.2 | D43: =(C43-C42)/C42 -> -0.002283105 | E43: 1161.86 | F43: =(E43-E42)/E42 -> -0.002335606
B44: 44449 | C44: 256.6 | D44: =(C44-C43)/C43 -> -0.021357742 | E44: 1152.02 | F44: =(E44-E43)/E43 -> -0.0084691787
B45: 44456 | C45: 240.65 | D45: =(C45-C44)/C44 -> -0.062159002 | E45: 1141.17 | F45: =(E45-E44)/E44 -> -0.0094182393
B46: 44463 | C46: 244.45 | D46: =(C46-C45)/C45 -> 0.015790567 | E46: 1155 | F46: =(E46-E45)/E45 -> 0.012119141
B47: 44470 | C47: 226.5 | D47: =(C47-C46)/C46 -> -0.073430149 | E47: 1164.43 | F47: =(E47-E46)/E46 -> 0.0081645022
B48: 44477 | C48: 232 | D48: =(C48-C47)/C47 -> 0.024282561 | E48: 1167.35 | F48: =(E48-E47)/E47 -> 0.0025076647
B49: 44484 | C49: 241.15 | D49: =(C49-C48)/C48 -> 0.039439655 | E49: 1197.57 | F49: =(E49-E48)/E48 -> 0.025887694
B50: 44491 | C50: 258.3 | D50: =(C50-C49)/C49 -> 0.071117562 | E50: 1217.71 | F50: =(E50-E49)/E49 -> 0.016817389
B51: 44498 | C51: 272.6 | D51: =(C51-C50)/C50 -> 0.055361982 | E51: 1192.78 | F51: =(E51-E50)/E50 -> -0.020472855
...

Sheet Antagelser
A1: Base forutsetninger
C2: 2026E | D2: 2027E | E2: 2028E | F2: 2029E | G2: 2030E | H2: 2031E | I2: 2032E | J2: 2033E | K2: 2034E | L2: 2035E
B3: Collection
B4: Omsetningsvekst | C4: 0.18 | D4: 0.08 | E4: 0.07 | F4: 0.06 | G4: 0.06 | H4: 0.055 | I4: 0.05 | J4: 0.045 | K4: 0.04 | L4: 0.035
B5: Bruttomargin | C5: 0.4 | D5: 0.405 | E5: 0.405 | F5: 0.405 | G5: 0.405 | H5: 0.405 | I5: 0.405 | J5: 0.405 | K5: 0.405 | L5: 0.405
B6: Vekst i driftskostnader | C6: 0.09 | D6: 0.04 | E6: 0.05 | F6: 0.05 | G6: 0.05 | H6: 0.05 | I6: 0.05 | J6: 0.045 | K6: 0.045 | L6: 0.04
B8: Recycling
B9: Omsetningsvekst | C9: -0.05 | D9: 0.08 | E9: 0.1 | F9: 0.08 | G9: 0.07 | H9: 0.055 | I9: 0.05 | J9: 0.045 | K9: 0.035 | L9: 0.03
B10: Bruttomargin | C10: 0.47 | D10: 0.49 | E10: 0.505 | F10: 0.515 | G10: 0.52 | H10: 0.52 | I10: 0.52 | J10: 0.52 | K10: 0.52 | L10: 0.52
B11: Vekst i driftskostnader | C11: -0.06 | D11: 0.02 | E11: 0.04 | F11: 0.04 | G11: 0.04 | H11: 0.04 | I11: 0.04 | J11: 0.04 | K11: 0.035 | L11: 0.03
B13: Food
B14: Omsetningsvekst | C14: 0.07 | D14: 0.07 | E14: 0.07 | F14: 0.065 | G14: 0.06 | H14: 0.0525 | I14: 0.05 | J14: 0.045 | K14: 0.04 | L14: 0.03
B15: Bruttomargin | C15: 0.44 | D15: 0.45 | E15: 0.455 | F15: 0.455 | G15: 0.455 | H15: 0.455 | I15: 0.455 | J15: 0.455 | K15: 0.455 | L15: 0.455
B16: Vekst i driftskostnader | C16: 0.05 | D16: 0.04 | E16: 0.04 | F16: 0.04 | G16: 0.04 | H16: 0.04 | I16: 0.04 | J16: 0.04 | K16: 0.04 | L16: 0.04
B19: Amortisering/omsetning | C19: 0.02 | D19: 0.019 | E19: 0.018 | F19: 0.017 | G19: 0.017 | H19: 0.016 | I19: 0.015 | J19: 0.014 | K19: 0.013 | L19: 0.012
B20: Skattesats | C20: 0.245 | D20: 0.245 | E20: 0.245 | F20: 0.245 | G20: 0.245 | H20: 0.245 | I20: 0.245 | J20: 0.245 | K20: 0.245 | L20: 0.245
B21: D&A/omsetning | C21: 0.085 | D21: 0.083 | E21: 0.08 | F21: 0.078 | G21: 0.075 | H21: 0.073 | I21: 0.071 | J21: 0.069 | K21: 0.067 | L21: 0.065
B22: Capex/Omsetning | C22: 0.1 | D22: 0.095 | E22: 0.09 | F22: 0.085 | G22: 0.08 | H22: 0.078 | I22: 0.078 | J22: 0.078 | K22: 0.078 | L22: 0.078
B23: Arbeidskapital/Omsetning | C23: 0.25 | D23: 0.245 | E23: 0.24 | F23: 0.235 | G23: 0.23 | H23: 0.23 | I23: 0.228 | J23: 0.226 | K23: 0.225 | L23: 0.225
A27: Bear forutsetninger
C28: 2026E | D28: 2027E | E28: 2028E | F28: 2029E | G28: 2030E | H28: =H2 -> 2031E | I28: =I2 -> 2032E | J28: =J2 -> 2033E | K28: =K2 -> 2034E | L28: =L2 -> 2035E
B29: Collection
B30: Omsetningsvekst | C30: 0.16 | D30: 0.07 | E30: 0.06 | F30: 0.05 | G30: 0.05 | H30: 0.045 | I30: 0.04 | J30: 0.035 | K30: 0.03 | L30: 0.025
B31: Bruttomargin | C31: 0.395 | D31: 0.4 | E31: 0.4 | F31: 0.402 | G31: 0.402 | H31: 0.402 | I31: 0.404 | J31: 0.405 | K31: 0.405 | L31: 0.405
B32: Vekst i driftskostnader | C32: 0.095 | D32: 0.05 | E32: 0.05 | F32: 0.055 | G32: 0.055 | H32: 0.045 | I32: 0.042 | J32: 0.04 | K32: 0.038 | L32: 0.035
B34: Recycling
B35: Omsetningsvekst | C35: -0.08 | D35: 0.05 | E35: 0.08 | F35: 0.07 | G35: 0.07 | H35: 0.045 | I35: 0.045 | J35: 0.04 | K35: 0.035 | L35: 0.03
B36: Bruttomargin | C36: 0.45 | D36: 0.47 | E36: 0.485 | F36: 0.495 | G36: 0.5 | H36: 0.505 | I36: 0.51 | J36: 0.513 | K36: 0.515 | L36: 0.515
B37: Vekst i driftskostnader | C37: -0.05 | D37: 0.03 | E37: 0.05 | F37: 0.05 | G37: 0.05 | H37: 0.03 | I37: 0.032 | J37: 0.032 | K37: 0.03 | L37: 0.028
B39: Food
B40: Omsetningsvekst | C40: 0.05 | D40: 0.05 | E40: 0.05 | F40: 0.045 | G40: 0.04 | H40: 0.04 | I40: 0.04 | J40: 0.035 | K40: 0.03 | L40: 0.025
B41: Bruttomargin | C41: 0.425 | D41: 0.435 | E41: 0.435 | F41: 0.44 | G41: 0.445 | H41: 0.448 | I41: 0.45 | J41: 0.452 | K41: 0.453 | L41: 0.455
B42: Vekst i driftskostnader | C42: 0.06 | D42: 0.05 | E42: 0.05 | F42: 0.05 | G42: 0.05 | H42: 0.035 | I42: 0.035 | J42: 0.033 | K42: 0.03 | L42: 0.028
B45: Amortisering/omsetning | C45: 0.02 | D45: 0.019 | E45: 0.018 | F45: 0.017 | G45: 0.017 | H45: 0.016 | I45: 0.015 | J45: 0.014 | K45: 0.013 | L45: 0.012
B46: Skattesats | C46: 0.25 | D46: 0.25 | E46: 0.25 | F46: 0.25 | G46: 0.25 | H46: 0.25 | I46: 0.25 | J46: 0.25 | K46: 0.25 | L46: 0.25
B47: D&A/omsetning | C47: 0.085 | D47: 0.083 | E47: 0.08 | F47: 0.078 | G47: 0.075 | H47: 0.073 | I47: 0.071 | J47: 0.069 | K47: 0.067 | L47: 0.065
B48: Capex/Omsetning | C48: 0.105 | D48: 0.1 | E48: 0.095 | F48: 0.09 | G48: 0.085 | H48: 0.088 | I48: 0.086 | J48: 0.084 | K48: 0.082 | L48: 0.08
B49: Arbeidskapital/Omsetning | C49: 0.255 | D49: 0.25 | E49: 0.245 | F49: 0.24 | G49: 0.235 | H49: 0.235 | I49: 0.233 | J49: 0.23 | K49: 0.228 | L49: 0.225
A53: Bull forutsetinger
C54: 2026E | D54: 2027E | E54: 2028E | F54: 2029E | G54: 2030E | H54: 2031E | I54: 2032E | J54: 2033E | K54: 2034E | L54: 2035E
...

Sheet Forecast Base
B2: Forecast Base
B4: COLLECTION | C4: 2023 | D4: 2024 | E4: 2025 | F4: 2026E | G4: 2027E | H4: 2028E | I4: 2029E | J4: 2030E | K4: 2031E | L4: 2032E | M4: 2033E | N4: 2034E | O4: 2035E
B5: Omsetning | C5: 697.4 | D5: 773.1 | E5: 740.5 | F5: =E5*(1+Antagelser!C4) -> 873.79 | G5: =F5*(1+Antagelser!D4) -> 943.6932 | H5: =G5*(1+Antagelser!E4) -> 1009.7517 | I5: =H5*(1+Antagelser!F4) -> 1070.3368 | J5: =I5*(1+Antagelser!G4) -> 1134.557 | K5: =J5*(1+Antagelser!H4) -> 1196.9577 | L5: =K5*(1+Antagelser!I4) -> 1256.8056 | M5: =L5*(1+Antagelser!J4) -> 1313.3618 | ... O5: =N5*(1+Antagelser!L4) -> 1413.7027
B6: Vekst | D6: =(D5-C5)/C5 -> 0.10854603 | E6: =(E5-D5)/D5 -> -0.042167895 | F6: =(F5-E5)/E5 -> 0.18 | G6: =(G5-F5)/F5 -> 0.08 | H6: =(H5-G5)/G5 -> 0.07 | I6: =(I5-H5)/H5 -> 0.06 | J6: =(J5-I5)/I5 -> 0.06 | K6: =(K5-J5)/J5 -> 0.055 | ... O6: =(O5-N5)/N5 -> 0.035
B7: Bruttomargin | C7: 0.399 | D7: 0.406 | E7: 0.417 | F7: =Antagelser!C5 -> 0.4 | G7: =Antagelser!D5 -> 0.405 | H7: =Antagelser!E5 -> 0.405 | I7: =Antagelser!F5 -> 0.405 | J7: =Antagelser!G5 -> 0.405 | K7: =Antagelser!H5 -> 0.405 | L7: =Antagelser!I5 -> 0.405 | M7: =Antagelser!J5 -> 0.405 | ... O7: =Antagelser!L5 -> 0.405
B8: Bruttobidrag | C8: =C5*C7 -> 278.2626 | D8: =D5*D7 -> 313.8786 | E8: =E5*E7 -> 308.7885 | F8: =F5*F7 -> 349.516 | G8: =G5*G7 -> 382.19575 | H8: =H5*H7 -> 408.94945 | I8: =I5*I7 -> 433.48642 | J8: =J5*J7 -> 459.4956 | ... O8: =O5*O7 -> 572.54957
B9: Driftskostnader | C9: 162.9 | D9: 183.2 | E9: 182.4 | F9: =E9*(1+Antagelser!C6) -> 198.816 | G9: =F9*(1+Antagelser!D6) -> 206.76864 | H9: =G9*(1+Antagelser!E6) -> 217.10707 | I9: =H9*(1+Antagelser!F6) -> 227.96243 | J9: =I9*(1+Antagelser!G6) -> 239.36055 | K9: =J9*(1+Antagelser!H6) -> 251.32857 | L9: =K9*(1+Antagelser!I6) -> 263.895 | M9: =L9*(1+Antagelser!J6) -> 275.77028 | ... O9: =N9*(1+Antagelser!L6) -> 299.70714
B10: Justert EBITA | C10: =C8-C9 -> 115.3626 | D10: =D8-D9 -> 130.6786 | E10: =E8-E9 -> 126.3885 | F10: =F8-F9 -> 150.7 | G10: =G8-G9 -> 175.42711 | H10: =H8-H9 -> 191.84238 | I10: =I8-I9 -> 205.52399 | J10: =J8-J9 -> 220.13505 | ... O10: =O8-O9 -> 272.84244
B11: Justert EBITA-margin | C11: =C10/C5 -> 0.16541812 | D11: =D10/D5 -> 0.16903195 | E11: =E10/E5 -> 0.17067995 | F11: =F10/F5 -> 0.17246707 | G11: =G10/G5 -> 0.18589421 | H11: =H10/H5 -> 0.18998965 | I11: =I10/I5 -> 0.19201805 | J11: =J10/J5 -> 0.19402731 | ... O11: =O10/O5 -> 0.19299846
B13: RECYCLING
B14: Omsetning | C14: 270.1 | D14: 265.8 | E14: 218.2 | F14: =E14*(1+Antagelser!C9) -> 207.29 | G14: =F14*(1+Antagelser!D9) -> 223.8732 | H14: =G14*(1+Antagelser!E9) -> 246.26052 | I14: =H14*(1+Antagelser!F9) -> 265.96136 | J14: =I14*(1+Antagelser!G9) -> 284.57866 | K14: =J14*(1+Antagelser!H9) -> 300.23048 | L14: =K14*(1+Antagelser!I9) -> 315.24201 | M14: =L14*(1+Antagelser!J9) -> 329.4279 | ... O14: =N14*(1+Antagelser!L9) -> 351.18661
B15: Vekst | D15: =(D14-C14)/C14 -> -0.01592003 | E15: =(E14-D14)/D14 -> -0.17908202 | F15: =(F14-E14)/E14 -> -0.05 | G15: =(G14-F14)/F14 -> 0.08 | H15: =(H14-G14)/G14 -> 0.1 | I15: =(I14-H14)/H14 -> 0.08 | J15: =(J14-I14)/I14 -> 0.07 | K15: =(K14-J14)/J14 -> 0.055 | ... O15: =(O14-N14)/N14 -> 0.03
B16: Bruttomargin | C16: 0.522 | D16: 0.525 | E16: 0.477 | F16: =Antagelser!C10 -> 0.47 | G16: =Antagelser!D10 -> 0.49 | H16: =Antagelser!E10 -> 0.505 | I16: =Antagelser!F10 -> 0.515 | J16: =Antagelser!G10 -> 0.52 | K16: =Antagelser!H10 -> 0.52 | L16: =Antagelser!I10 -> 0.52 | M16: =Antagelser!J10 -> 0.52 | ... O16: =Antagelser!L10 -> 0.52
B17: Bruttobidrag | C17: =C16*C14 -> 140.9922 | D17: =D16*D14 -> 139.545 | E17: =E16*E14 -> 104.0814 | F17: =F16*F14 -> 97.4263 | G17: =G16*G14 -> 109.69787 | H17: =H16*H14 -> 124.36156 | I17: =I16*I14 -> 136.9701 | J17: =J16*J14 -> 147.9809 | ... O17: =O16*O14 -> 182.61704
B18: Driftskostnader | C18: 79.5 | D18: 79.4 | E18: 80.6 | F18: =E18*(1+Antagelser!C11) -> 75.764 | G18: =F18*(1+Antagelser!D11) -> 77.27928 | H18: =G18*(1+Antagelser!E11) -> 80.370451 | I18: =H18*(1+Antagelser!F11) -> 83.585269 | J18: =I18*(1+Antagelser!G11) -> 86.92868 | K18: =J18*(1+Antagelser!H11) -> 90.405827 | L18: =K18*(1+Antagelser!I11) -> 94.02206 | M18: =L18*(1+Antagelser!J11) -> 97.782943 | ... O18: =N18*(1+Antagelser!L11) -> 104.24151
B19: Justert EBITA | C19: =C17-C18 -> 61.4922 | D19: =D17-D18 -> 60.145 | E19: =E17-E18 -> 23.4814 | F19: =F17-F18 -> 21.6623 | G19: =G17-G18 -> 32.418588 | H19: =H17-H18 -> 43.991111 | I19: =I17-I18 -> 53.384832 | J19: =J17-J18 -> 61.052222 | ... O19: =O17-O18 -> 78.375531
B20: Justert EBITA-margin | C20: =C19/C14 -> 0.22766457 | D20: =D19/D14 -> 0.22627916 | E20: =E19/E14 -> 0.10761412 | F20: =F19/F14 -> 0.10450239 | G20: =G19/G14 -> 0.14480781 | H20: =H19/H14 -> 0.17863648 | I20: =I19/I14 -> 0.20072401 | J20: =J19/J14 -> 0.21453549 | ... O20: =O19/O14 -> 0.22317346
B22: FOOD
B23: Omsetning | C23: 319.6 | D23: 310.9 | E23: 328 | F23: =E23*(1+Antagelser!C14) -> 350.96 | G23: =F23*(1+Antagelser!D14) -> 375.5272 | H23: =G23*(1+Antagelser!E14) -> 401.8141 | I23: =H23*(1+Antagelser!F14) -> 427.93202 | J23: =I23*(1+Antagelser!G14) -> 453.60794 | K23: =J23*(1+Antagelser!H14) -> 477.42236 | L23: =K23*(1+Antagelser!I14) -> 501.29348 | M23: =L23*(1+Antagelser!J14) -> 523.85168 | ... O23: =N23*(1+Antagelser!L14) -> 561.14992
B24: Vekst | D24: =(D23-C23)/C23 -> -0.027221527 | E24: =(E23-D23)/D23 -> 0.055001608 | F24: =(F23-E23)/E23 -> 0.07 | G24: =(G23-F23)/F23 -> 0.07 | H24: =(H23-G23)/G23 -> 0.07 | I24: =(I23-H23)/H23 -> 0.065 | J24: =(J23-I23)/I23 -> 0.06 | K24: =(K23-J23)/J23 -> 0.0525 | ... O24: =(O23-N23)/N23 -> 0.03
B25: Bruttomargin | C25: 0.407 | D25: 0.429 | E25: 0.469 | F25: =Antagelser!C15 -> 0.44 | G25: =Antagelser!D15 -> 0.45 | H25: =Antagelser!E15 -> 0.455 | I25: =Antagelser!F15 -> 0.455 | J25: =Antagelser!G15 -> 0.455 | K25: =Antagelser!H15 -> 0.455 | L25: =Antagelser!I15 -> 0.455 | M25: =Antagelser!J15 -> 0.455 | ... O25: =Antagelser!L15 -> 0.455
B26: Bruttobidrag | C26: =C23*C25 -> 130.0772 | D26: =D23*D25 -> 133.3761 | E26: =E23*E25 -> 153.832 | F26: =F23*F25 -> 154.4224 | G26: =G23*G25 -> 168.98724 | H26: =H23*H25 -> 182.82542 | I26: =I23*I25 -> 194.70907 | J26: =J23*J25 -> 206.39161 | ... O26: =O23*O25 -> 255.32322
B27: Driftskostnader | C27: 122.4 | D27: 112.6 | E27: 110.3 | F27: =E27*(1+Antagelser!C16) -> 115.815 | G27: =F27*(1+Antagelser!D16) -> 120.4476 | H27: =G27*(1+Antagelser!E16) -> 125.2655 | I27: =H27*(1+Antagelser!F16) -> 130.27612 | J27: =I27*(1+Antagelser!G16) -> 135.48717 | K27: =J27*(1+Antagelser!H16) -> 140.90666 | L27: =K27*(1+Antagelser!I16) -> 146.54292 | M27: =L27*(1+Antagelser!J16) -> 152.40464 | ... O27: =N27*(1+Antagelser!L16) -> 164.84086
B28: Justert EBITA | C28: =C26-C27 -> 7.6772 | D28: =D26-D27 -> 20.7761 | E28: =E26-E27 -> 43.532 | F28: =F26-F27 -> 38.6074 | G28: =G26-G27 -> 48.53964 | H28: =H26-H27 -> 57.559913 | I28: =I26-I27 -> 64.432945 | J28: =J26-J27 -> 70.904444 | ... O28: =O26-O27 -> 90.482358
B29: Justert EBITA-margin | C29: =C28/C23 -> 0.024021277 | D29: =D28/D23 -> 0.066825667 | E29: =E28/E23 -> 0.13271951 | F29: =F28/F23 -> 0.11000513 | G29: =G28/G23 -> 0.12925732 | H29: =H28/H23 -> 0.14325011 | I29: =I28/I23 -> 0.15056818 | J29: =J28/J23 -> 0.15631218 | ... O29: =O28/O23 -> 0.16124453
B31: HORIZON
B32: Omsetning | C32: 0.8 | D32: 7.4 | E32: 32.3 | F32: 48 | G32: 60 | H32: 75 | I32: 90 | J32: 105 | K32: 118 | L32: 130 | M32: 141 | N32: 151 | O32: 160
B33: Vekst | D33: =(D32-C32)/C32 -> 8.25 | E33: =(E32-D32)/D32 -> 3.3648649 | F33: =(F32-E32)/E32 -> 0.48606811 | G33: =(G32-F32)/F32 -> 0.25 | H33: =(H32-G32)/G32 -> 0.25 | I33: =(I32-H32)/H32 -> 0.2 | J33: =(J32-I32)/I32 -> 0.16666667 | K33: =(K32-J32)/J32 -> 0.12380952 | ... O33: =(O32-N32)/N32 -> 0.059602649
B34: Bruttomargin | C34: -1.194 | D34: 0.501 | E34: 0.594 | F34: 0.6 | G34: 0.62 | H34: 0.63 | I34: 0.64 | J34: 0.65 | K34: 0.655 | L34: 0.66 | M34: 0.66 | N34: 0.66 | O34: 0.66
B35: Bruttobidrag | C35: =C34*C32 -> -0.9552 | D35: =D34*D32 -> 3.7074 | E35: =E34*E32 -> 19.1862 | F35: =F34*F32 -> 28.8 | G35: =G34*G32 -> 37.2 | H35: =H34*H32 -> 47.25 | I35: =I34*I32 -> 57.6 | J35: =J34*J32 -> 68.25 | ... O35: =O34*O32 -> 105.6
B36: Driftskostnader | C36: 7.2 | D36: 11.1 | E36: 23.9 | F36: 29 | G36: 34 | H36: 40 | I36: 48 | J36: 52 | K36: 59 | L36: 65 | M36: 71 | N36: 77 | O36: 82
B37: EBITA | C37: =C35-C36 -> -8.1552 | D37: =D35-D36 -> -7.3926 | E37: =E35-E36 -> -4.7138 | F37: =F35-F36 -> -0.2 | G37: =G35-G36 -> 3.2 | H37: =H35-H36 -> 7.25 | I37: =I35-I36 -> 9.6 | J37: =J35-J36 -> 16.25 | ... O37: =O35-O36 -> 23.6
B38: EBITA-margin | C38: =C37/C32 -> -10.194 | D38: =D37/D32 -> -0.999 | E38: =E37/E32 -> -0.14593808 | F38: =F37/F32 -> -0.0041666667 | G38: =G37/G32 -> 0.053333333 | H38: =H37/H32 -> 0.096666667 | I38: =I37/I32 -> 0.10666667 | J38: =J37/J32 -> 0.1547619 | ... O38: =O37/O32 -> 0.1475
B40: KONSERNFUNKSJONER | C40: -14.7 | D40: -22.7 | E40: -17 | F40: =(C40+D40+E40)/3 -> -18.133333 | G40: -18.7 | H40: -19.3 | I40: -19.9 | J40: -20.5 | K40: -21.5 | L40: =-22.5 -> -22.5 | M40: -23.5 | N40: -24.5 | O40: -25.5
B41: EBITA | C41: =C10+C19+C28+C37+C40 -> 161.6768 | D41: =D10+D19+D28+D37+D40 -> 181.5071 | E41: =E10+E19+E28+E37+E40 -> 171.6881 | F41: =F10+F19+F28+F37+F40 -> 192.63637 | G41: =G10+G19+G28+G37+G40 -> 240.88533 | H41: =H10+H19+H28+H37+H40 -> 281.3434 | I41: =I10+I19+I28+I37+I40 -> 313.04177 | J41: =J10+J19+J28+J37+J40 -> 347.84172 | ... O41: =O10+O19+O28+O37+O40 -> 439.80032
B43: TOMRA GROUP
B44: Omsetning | C44: =C32+C23+C14+C5 -> 1287.9 | D44: =D32+D23+D14+D5 -> 1357.2 | E44: =E32+E23+E14+E5 -> 1319 | F44: =F32+F23+F14+F5 -> 1480.04 | G44: =G32+G23+G14+G5 -> 1603.0936 | H44: =H32+H23+H14+H5 -> 1732.8263 | I44: =I32+I23+I14+I5 -> 1854.2302 | J44: =J32+J23+J14+J5 -> 1977.7436 | ... O44: =O32+O23+O14+O5 -> 2486.0392
B45: Vekst | D45: =(D44-C44)/C44 -> 0.053808526 | E45: =(E44-D44)/D44 -> -0.028146183 | F45: =(F44-E44)/E44 -> 0.12209249 | G45: =(G44-F44)/F44 -> 0.083142077 | H45: =(H44-G44)/G44 -> 0.080926496 | I45: =(I44-H44)/H44 -> 0.070061182 | J45: =(J44-I44)/I44 -> 0.0666117 | K45: =(K44-J44)/J44 -> 0.058079762 | ... O45: =(O44-N44)/N44 -> 0.034702905
B46: Bruttobidrag | C46: =C35+C26+C17+C8 -> 548.3768 | D46: =D35+D26+D17+D8 -> 590.5071 | E46: =E35+E26+E17+E8 -> 585.8881 | F46: =F35+F26+F17+F8 -> 630.1647 | G46: =G35+G26+G17+G8 -> 698.08085 | H46: =H35+H26+H17+H8 -> 763.38643 | I46: =I35+I26+I17+I8 -> 822.76559 | J46: =J35+J26+J17+J8 -> 882.11812 | ... O46: =O35+O26+O17+O8 -> 1116.0898
B47: Bruttomargin | C47: =C46/C44 -> 0.42579144 | D47: =D46/D44 -> 0.43509218 | E47: =E46/E44 -> 0.44419113 | F47: =F46/F44 -> 0.42577545 | G47: =G46/G44 -> 0.43545857 | H47: =H46/H44 -> 0.4405441 | I47: =I46/I44 -> 0.44372354 | J47: =J46/J44 -> 0.44602248 | ... O47: =O46/O44 -> 0.44894297
...

Sheet Forecast Bear
B2: Forecast Bear
B4: COLLECTION | C4: 2023 | D4: 2024 | E4: 2025 | F4: 2026E | G4: 2027E | H4: 2028E | I4: 2029E | J4: 2030E | K4: 2031E | L4: 2032E | M4: 2033E | N4: 2034E | O4: 2035E
B5: Omsetning | C5: 697.4 | D5: 773.1 | E5: 740.5 | F5: =E5*(1+Antagelser!C30) -> 858.98 | G5: =F5*(1+Antagelser!D30) -> 919.1086 | H5: =G5*(1+Antagelser!E30) -> 974.25512 | I5: =H5*(1+Antagelser!F30) -> 1022.9679 | J5: =I5*(1+Antagelser!G30) -> 1074.1163 | K5: =J5*(1+Antagelser!H30) -> 1122.4515 | L5: =K5*(1+Antagelser!I30) -> 1167.3496 | M5: =L5*(1+Antagelser!J30) -> 1208.2068 | ... O5: =N5*(1+Antagelser!L30) -> 1275.5643
B6: Vekst | D6: =(D5-C5)/C5 -> 0.10854603 | E6: =(E5-D5)/D5 -> -0.042167895 | F6: =(F5-E5)/E5 -> 0.16 | G6: =(G5-F5)/F5 -> 0.07 | H6: =(H5-G5)/G5 -> 0.06 | I6: =(I5-H5)/H5 -> 0.05 | J6: =(J5-I5)/I5 -> 0.05 | K6: =(K5-J5)/J5 -> 0.045 | ... O6: =(O5-N5)/N5 -> 0.025
B7: Bruttomargin | C7: 0.399 | D7: 0.406 | E7: 0.417 | F7: =Antagelser!C31 -> 0.395 | G7: =Antagelser!D31 -> 0.4 | H7: =Antagelser!E31 -> 0.4 | I7: =Antagelser!F31 -> 0.402 | J7: =Antagelser!G31 -> 0.402 | K7: =Antagelser!H31 -> 0.402 | L7: =Antagelser!I31 -> 0.404 | M7: =Antagelser!J31 -> 0.405 | ... O7: =Antagelser!L31 -> 0.405
B8: Bruttobidrag | C8: =C5*C7 -> 278.2626 | D8: =D5*D7 -> 313.8786 | E8: =E5*E7 -> 308.7885 | F8: =F5*F7 -> 339.2971 | G8: =G5*G7 -> 367.64344 | H8: =H5*H7 -> 389.70205 | I8: =I5*I7 -> 411.23308 | J8: =J5*J7 -> 431.79474 | ... O8: =O5*O7 -> 516.60355
B9: Driftskostnader | C9: 162.9 | D9: 183.2 | E9: 182.4 | F9: =E9*(1+Antagelser!C32) -> 199.728 | G9: =F9*(1+Antagelser!D32) -> 209.7144 | H9: =G9*(1+Antagelser!E32) -> 220.20012 | I9: =H9*(1+Antagelser!F32) -> 232.31113 | J9: =I9*(1+Antagelser!G32) -> 245.08824 | K9: =J9*(1+Antagelser!H32) -> 256.11721 | L9: =K9*(1+Antagelser!I32) -> 266.87413 | M9: =L9*(1+Antagelser!J32) -> 277.5491 | ... O9: =N9*(1+Antagelser!L32) -> 298.17932
B10: Justert EBITA | C10: =C8-C9 -> 115.3626 | D10: =D8-D9 -> 130.6786 | E10: =E8-E9 -> 126.3885 | F10: =F8-F9 -> 139.5691 | G10: =G8-G9 -> 157.92904 | H10: =H8-H9 -> 169.50193 | I10: =I8-I9 -> 178.92196 | J10: =J8-J9 -> 186.7065 | ... O10: =O8-O9 -> 218.42423
B11: Justert EBITA-margin | C11: =C10/C5 -> 0.16541812 | D11: =D10/D5 -> 0.16903195 | E11: =E10/E5 -> 0.17067995 | F11: =F10/F5 -> 0.16248236 | G11: =G10/G5 -> 0.17182849 | H11: =H10/H5 -> 0.17398105 | I11: =I10/I5 -> 0.17490477 | J11: =J10/J5 -> 0.17382336 | ... O11: =O10/O5 -> 0.17123733
B13: RECYCLING
B14: Omsetning | C14: 270.1 | D14: 265.8 | E14: 218.2 | F14: =E14*(1+Antagelser!C35) -> 200.744 | G14: =F14*(1+Antagelser!D35) -> 210.7812 | H14: =G14*(1+Antagelser!E35) -> 227.6437 | I14: =H14*(1+Antagelser!F35) -> 243.57875 | J14: =I14*(1+Antagelser!G35) -> 260.62927 | K14: =J14*(1+Antagelser!H35) -> 272.35758 | L14: =K14*(1+Antagelser!I35) -> 284.61368 | M14: =L14*(1+Antagelser!J35) -> 295.99822 | ... O14: =N14*(1+Antagelser!L35) -> 315.54891
B15: Vekst | D15: =(D14-C14)/C14 -> -0.01592003 | E15: =(E14-D14)/D14 -> -0.17908202 | F15: =(F14-E14)/E14 -> -0.08 | G15: =(G14-F14)/F14 -> 0.05 | H15: =(H14-G14)/G14 -> 0.08 | I15: =(I14-H14)/H14 -> 0.07 | J15: =(J14-I14)/I14 -> 0.07 | K15: =(K14-J14)/J14 -> 0.045 | ... O15: =(O14-N14)/N14 -> 0.03
B16: Bruttomargin | C16: 0.522 | D16: 0.525 | E16: 0.477 | F16: =Antagelser!C36 -> 0.45 | G16: =Antagelser!D36 -> 0.47 | H16: =Antagelser!E36 -> 0.485 | I16: =Antagelser!F36 -> 0.495 | J16: =Antagelser!G36 -> 0.5 | K16: =Antagelser!H36 -> 0.505 | L16: =Antagelser!I36 -> 0.51 | M16: =Antagelser!J36 -> 0.513 | ... O16: =Antagelser!L36 -> 0.515
B17: Bruttobidrag | C17: =C16*C14 -> 140.9922 | D17: =D16*D14 -> 139.545 | E17: =E16*E14 -> 104.0814 | F17: =F16*F14 -> 90.3348 | G17: =G16*G14 -> 99.067164 | H17: =H16*H14 -> 110.40719 | I17: =I16*I14 -> 120.57148 | J17: =J16*J14 -> 130.31463 | ... O17: =O16*O14 -> 162.50769
B18: Driftskostnader | C18: 79.5 | D18: 79.4 | E18: 80.6 | F18: =E18*(1+Antagelser!C37) -> 76.57 | G18: =F18*(1+Antagelser!D37) -> 78.8671 | H18: =G18*(1+Antagelser!E37) -> 82.810455 | I18: =H18*(1+Antagelser!F37) -> 86.950978 | J18: =I18*(1+Antagelser!G37) -> 91.298527 | K18: =J18*(1+Antagelser!H37) -> 94.037482 | L18: =K18*(1+Antagelser!I37) -> 97.046682 | M18: =L18*(1+Antagelser!J37) -> 100.15218 | ... O18: =N18*(1+Antagelser!L37) -> 106.04513
B19: Justert EBITA | C19: =C17-C18 -> 61.4922 | D19: =D17-D18 -> 60.145 | E19: =E17-E18 -> 23.4814 | F19: =F17-F18 -> 13.7648 | G19: =G17-G18 -> 20.200064 | H19: =H17-H18 -> 27.596738 | I19: =I17-I18 -> 33.620506 | J19: =J17-J18 -> 39.016107 | ... O19: =O17-O18 -> 56.462557
B20: Justert EBITA-margin | C20: =C19/C14 -> 0.22766457 | D20: =D19/D14 -> 0.22627916 | E20: =E19/E14 -> 0.10761412 | F20: =F19/F14 -> 0.068568924 | G20: =G19/G14 -> 0.095834277 | H20: =H19/H14 -> 0.12122777 | I20: =I19/I14 -> 0.13802725 | J20: =J19/J14 -> 0.14969964 | ... O20: =O19/O14 -> 0.17893441
B22: FOOD
B23: Omsetning | C23: 319.6 | D23: 310.9 | E23: 328 | F23: =E23*(1+Antagelser!C40) -> 344.4 | G23: =F23*(1+Antagelser!D40) -> 361.62 | H23: =G23*(1+Antagelser!E40) -> 379.701 | I23: =H23*(1+Antagelser!F40) -> 396.78755 | J23: =I23*(1+Antagelser!G40) -> 412.65905 | K23: =J23*(1+Antagelser!H40) -> 429.16541 | L23: =K23*(1+Antagelser!I40) -> 446.33203 | M23: =L23*(1+Antagelser!J40) -> 461.95365 | ... O23: =N23*(1+Antagelser!L40) -> 487.70756
B24: Vekst | D24: =(D23-C23)/C23 -> -0.027221527 | E24: =(E23-D23)/D23 -> 0.055001608 | F24: =(F23-E23)/E23 -> 0.05 | G24: =(G23-F23)/F23 -> 0.05 | H24: =(H23-G23)/G23 -> 0.05 | I24: =(I23-H23)/H23 -> 0.045 | J24: =(J23-I23)/I23 -> 0.04 | K24: =(K23-J23)/J23 -> 0.04 | ... O24: =(O23-N23)/N23 -> 0.025
B25: Bruttomargin | C25: 0.407 | D25: 0.429 | E25: 0.469 | F25: =Antagelser!C41 -> 0.425 | G25: =Antagelser!D41 -> 0.435 | H25: =Antagelser!E41 -> 0.435 | I25: =Antagelser!F41 -> 0.44 | J25: =Antagelser!G41 -> 0.445 | K25: =Antagelser!H41 -> 0.448 | L25: =Antagelser!I41 -> 0.45 | M25: =Antagelser!J41 -> 0.452 | ... O25: =Antagelser!L41 -> 0.455
B26: Bruttobidrag | C26: =C23*C25 -> 130.0772 | D26: =D23*D25 -> 133.3761 | E26: =E23*E25 -> 153.832 | F26: =F23*F25 -> 146.37 | G26: =G23*G25 -> 157.3047 | H26: =H23*H25 -> 165.16994 | I26: =I23*I25 -> 174.58652 | J26: =J23*J25 -> 183.63328 | ... O26: =O23*O25 -> 221.90694
B27: Driftskostnader | C27: 122.4 | D27: 112.6 | E27: 110.3 | F27: =E27*(1+Antagelser!C42) -> 116.918 | G27: =F27*(1+Antagelser!D42) -> 122.7639 | H27: =G27*(1+Antagelser!E42) -> 128.9021 | I27: =H27*(1+Antagelser!F42) -> 135.3472 | J27: =I27*(1+Antagelser!G42) -> 142.11456 | K27: =J27*(1+Antagelser!H42) -> 147.08857 | L27: =K27*(1+Antagelser!I42) -> 152.23667 | M27: =L27*(1+Antagelser!J42) -> 157.26048 | ... O27: =N27*(1+Antagelser!L42) -> 166.51369
B28: Justert EBITA | C28: =C26-C27 -> 7.6772 | D28: =D26-D27 -> 20.7761 | E28: =E26-E27 -> 43.532 | F28: =F26-F27 -> 29.452 | G28: =G26-G27 -> 34.5408 | H28: =H26-H27 -> 36.26784 | I28: =I26-I27 -> 39.23932 | J28: =J26-J27 -> 41.518716 | ... O28: =O26-O27 -> 55.393255
B29: Justert EBITA-margin | C29: =C28/C23 -> 0.024021277 | D29: =D28/D23 -> 0.066825667 | E29: =E28/E23 -> 0.13271951 | F29: =F28/F23 -> 0.085516841 | G29: =G28/G23 -> 0.095516841 | H29: =H28/H23 -> 0.095516841 | I29: =I28/I23 -> 0.09889252 | J29: =J28/J23 -> 0.10061264 | ... O29: =O28/O23 -> 0.11357883
B31: HORIZON
B32: Omsetning | C32: 0.8 | D32: 7.4 | E32: 32.3 | F32: 48 | G32: =60*0.85 -> 51 | H32: =75*0.85 -> 63.75 | I32: =90*0.85 -> 76.5 | J32: =105*0.85 -> 89.25 | K32: ='Forecast Base'!K32*0.85 -> 100.3 | L32: ='Forecast Base'!L32*0.85 -> 110.5 | M32: ='Forecast Base'!M32*0.85 -> 119.85 | N32: ='Forecast Base'!N32*0.85 -> 128.35 | O32: ='Forecast Base'!O32*0.85 -> 136
B33: Vekst | D33: =(D32-C32)/C32 -> 8.25 | E33: =(E32-D32)/D32 -> 3.3648649 | F33: =(F32-E32)/E32 -> 0.48606811 | G33: =(G32-F32)/F32 -> 0.0625 | H33: =(H32-G32)/G32 -> 0.25 | I33: =(I32-H32)/H32 -> 0.2 | J33: =(J32-I32)/I32 -> 0.16666667 | K33: =(K32-J32)/J32 -> 0.12380952 | ... O33: =(O32-N32)/N32 -> 0.059602649
B34: Bruttomargin | C34: -1.194 | D34: 0.501 | E34: 0.594 | F34: 0.6 | G34: 0.6 | H34: 0.6 | I34: 0.6 | J34: 0.6 | K34: 0.6 | L34: 0.6 | M34: 0.6 | N34: 0.6 | O34: 0.6
B35: Bruttobidrag | C35: =C34*C32 -> -0.9552 | D35: =D34*D32 -> 3.7074 | E35: =E34*E32 -> 19.1862 | F35: =F34*F32 -> 28.8 | G35: =G34*G32 -> 30.6 | H35: =H34*H32 -> 38.25 | I35: =I34*I32 -> 45.9 | J35: =J34*J32 -> 53.55 | ... O35: =O34*O32 -> 81.6
B36: Driftskostnader | C36: 7.2 | D36: 11.1 | E36: 23.9 | F36: 29 | G36: =34*0.95 -> 32.3 | H36: =40*0.95 -> 38 | I36: =48*0.95 -> 45.6 | J36: =52*0.95 -> 49.4 | K36: ='Forecast Base'!K36*0.95 -> 56.05 | L36: ='Forecast Base'!L36*0.95 -> 61.75 | M36: ='Forecast Base'!M36*0.95 -> 67.45 | N36: ='Forecast Base'!N36*0.95 -> 73.15 | O36: ='Forecast Base'!O36*0.95 -> 77.9
B37: EBITA | C37: =C35-C36 -> -8.1552 | D37: =D35-D36 -> -7.3926 | E37: =E35-E36 -> -4.7138 | F37: =F35-F36 -> -0.2 | G37: =G35-G36 -> -1.7 | H37: =H35-H36 -> 0.25 | I37: =I35-I36 -> 0.3 | J37: =J35-J36 -> 4.15 | ... O37: =O35-O36 -> 3.7
B38: EBITA-margin | C38: =C37/C32 -> -10.194 | D38: =D37/D32 -> -0.999 | E38: =E37/E32 -> -0.14593808 | F38: =F37/F32 -> -0.0041666667 | G38: =G37/G32 -> -0.033333333 | H38: =H37/H32 -> 0.0039215686 | I38: =I37/I32 -> 0.0039215686 | J38: =J37/J32 -> 0.046498599 | ... O38: =O37/O32 -> 0.027205882
B40: KONSERNFUNKSJONER | C40: -14.7 | D40: -22.7 | E40: -17 | F40: =(C40+D40+E40)/3 -> -18.133333 | G40: -18.7 | H40: -19.3 | I40: -19.9 | J40: -20.5 | K40: ='Forecast Base'!K40 -> -21.5 | L40: ='Forecast Base'!L40 -> -22.5 | M40: ='Forecast Base'!M40 -> -23.5 | N40: ='Forecast Base'!N40 -> -24.5 | O40: ='Forecast Base'!O40 -> -25.5
B41: EBITA | C41: =C10+C19+C28+C37+C40 -> 161.6768 | D41: =D10+D19+D28+D37+D40 -> 181.5071 | E41: =E10+E19+E28+E37+E40 -> 171.6881 | F41: =F10+F19+F28+F37+F40 -> 164.45257 | G41: =G10+G19+G28+G37+G40 -> 192.2699 | H41: =H10+H19+H28+H37+H40 -> 214.3165 | I41: =I10+I19+I28+I37+I40 -> 232.18178 | J41: =J10+J19+J28+J37+J40 -> 250.89132 | ... O41: =O10+O19+O28+O37+O40 -> 308.48004
B43: TOMRA GROUP
B44: Omsetning | C44: =C32+C23+C14+C5 -> 1287.9 | D44: =D32+D23+D14+D5 -> 1357.2 | E44: =E32+E23+E14+E5 -> 1319 | F44: =F32+F23+F14+F5 -> 1452.124 | G44: =G32+G23+G14+G5 -> 1542.5098 | H44: =H32+H23+H14+H5 -> 1645.3498 | I44: =I32+I23+I14+I5 -> 1739.8342 | J44: =J32+J23+J14+J5 -> 1836.6546 | ... O44: =O32+O23+O14+O5 -> 2214.8208
B45: Vekst | D45: =(D44-C44)/C44 -> 0.053808526 | E45: =(E44-D44)/D44 -> -0.028146183 | F45: =(F44-E44)/E44 -> 0.10092798 | G45: =(G44-F44)/F44 -> 0.062243858 | H45: =(H44-G44)/G44 -> 0.066670573 | I45: =(I44-H44)/H44 -> 0.057425089 | J45: =(J44-I44)/I44 -> 0.055649216 | K45: =(K44-J44)/J44 -> 0.047706255 | ... O45: =(O44-N44)/N44 -> 0.027771747
B46: Bruttobidrag | C46: =C35+C26+C17+C8 -> 548.3768 | D46: =D35+D26+D17+D8 -> 590.5071 | E46: =E35+E26+E17+E8 -> 585.8881 | F46: =F35+F26+F17+F8 -> 604.8019 | G46: =G35+G26+G17+G8 -> 654.6153 | H46: =H35+H26+H17+H8 -> 703.52917 | I46: =I35+I26+I17+I8 -> 752.29109 | J46: =J35+J26+J17+J8 -> 799.29265 | ... O46: =O35+O26+O17+O8 -> 982.61818
B47: Bruttomargin | C47: =C46/C44 -> 0.42579144 | D47: =D46/D44 -> 0.43509218 | E47: =E46/E44 -> 0.44419113 | F47: =F46/F44 -> 0.41649467 | G47: =G46/G44 -> 0.42438324 | H47: =H46/H44 -> 0.42758638 | I47: =I46/I44 -> 0.43239241 | J47: =J46/J44 -> 0.43518942 | ... O47: =O46/O44 -> 0.44365584
...

Sheet Forecast Bull
B2: Forecast Bull
B4: COLLECTION | C4: 2023 | D4: 2024 | E4: 2025 | F4: 2026E | G4: 2027E | H4: 2028E | I4: 2029E | J4: 2030E | K4: 2031E | L4: 2032E | M4: 2033E | N4: 2034E | O4: 2035E
B5: Omsetning | C5: 697.4 | D5: 773.1 | E5: 740.5 | F5: =E5*(1+Antagelser!C56) -> 881.195 | G5: =F5*(1+Antagelser!D56) -> 960.50255 | H5: =G5*(1+Antagelser!E56) -> 1046.9478 | I5: =H5*(1+Antagelser!F56) -> 1135.9383 | J5: =I5*(1+Antagelser!G56) -> 1226.8134 | K5: =J5*(1+Antagelser!H56) -> 1306.5563 | L5: =K5*(1+Antagelser!I56) -> 1384.9497 | M5: =L5*(1+Antagelser!J56) -> 1461.1219 | ... O5: =N5*(1+Antagelser!L56) -> 1603.216
B6: Vekst | D6: =(D5-C5)/C5 -> 0.10854603 | E6: =(E5-D5)/D5 -> -0.042167895 | F6: =(F5-E5)/E5 -> 0.19 | G6: =(G5-F5)/F5 -> 0.09 | H6: =(H5-G5)/G5 -> 0.09 | I6: =(I5-H5)/H5 -> 0.085 | J6: =(J5-I5)/I5 -> 0.08 | K6: =(K5-J5)/J5 -> 0.065 | ... O6: =(O5-N5)/N5 -> 0.045
B7: Bruttomargin | C7: 0.399 | D7: 0.406 | E7: 0.417 | F7: =Antagelser!C57 -> 0.41 | G7: =Antagelser!D57 -> 0.415 | H7: =Antagelser!E57 -> 0.415 | I7: =Antagelser!F57 -> 0.418 | J7: =Antagelser!G57 -> 0.418 | K7: =Antagelser!H57 -> 0.418 | L7: =Antagelser!I57 -> 0.418 | M7: =Antagelser!J57 -> 0.418 | ... O7: =Antagelser!L57 -> 0.418
B8: Bruttobidrag | C8: =C5*C7 -> 278.2626 | D8: =D5*D7 -> 313.8786 | E8: =E5*E7 -> 308.7885 | F8: =F5*F7 -> 361.28995 | G8: =G5*G7 -> 398.60856 | H8: =H5*H7 -> 434.48333 | I8: =I5*I7 -> 474.82223 | J8: =J5*J7 -> 512.808 | ... O8: =O5*O7 -> 670.14428
B9: Driftskostnader | C9: 162.9 | D9: 183.2 | E9: 182.4 | F9: =E9*(1+Antagelser!C58) -> 196.992 | G9: =F9*(1+Antagelser!D58) -> 202.90176 | H9: =G9*(1+Antagelser!E58) -> 211.01783 | I9: =H9*(1+Antagelser!F58) -> 219.45854 | J9: =I9*(1+Antagelser!G58) -> 228.23689 | K9: =J9*(1+Antagelser!H58) -> 243.07228 | L9: =K9*(1+Antagelser!I58) -> 257.65662 | M9: =L9*(1+Antagelser!J58) -> 271.82773 | ... O9: =N9*(1+Antagelser!L58) -> 298.26298
B10: Justert EBITA | C10: =C8-C9 -> 115.3626 | D10: =D8-D9 -> 130.6786 | E10: =E8-E9 -> 126.3885 | F10: =F8-F9 -> 164.29795 | G10: =G8-G9 -> 195.7068 | H10: =H8-H9 -> 223.4655 | I10: =I8-I9 -> 255.36368 | J10: =J8-J9 -> 284.57112 | ... O10: =O8-O9 -> 371.8813
B11: Justert EBITA-margin | C11: =C10/C5 -> 0.16541812 | D11: =D10/D5 -> 0.16903195 | E11: =E10/E5 -> 0.17067995 | F11: =F10/F5 -> 0.18644903 | G11: =G10/G5 -> 0.20375458 | H11: =H10/H5 -> 0.21344474 | I11: =I10/I5 -> 0.22480418 | J11: =J10/J5 -> 0.23195958 | ... O11: =O10/O5 -> 0.23195958
B13: RECYCLING
B14: Omsetning | C14: 270.1 | D14: 265.8 | E14: 218.2 | F14: =E14*(1+Antagelser!C61) -> 211.654 | G14: =F14*(1+Antagelser!D61) -> 232.8194 | H14: =G14*(1+Antagelser!E61) -> 260.75773 | I14: =H14*(1+Antagelser!F61) -> 286.8335 | J14: =I14*(1+Antagelser!G61) -> 311.21435 | K14: =J14*(1+Antagelser!H61) -> 331.44328 | L14: =K14*(1+Antagelser!I61) -> 351.32988 | M14: =L14*(1+Antagelser!J61) -> 370.65302 | ... O14: =N14*(1+Antagelser!L61) -> 404.7531
B15: Vekst | D15: =(D14-C14)/C14 -> -0.01592003 | E15: =(E14-D14)/D14 -> -0.17908202 | F15: =(F14-E14)/E14 -> -0.03 | G15: =(G14-F14)/F14 -> 0.1 | H15: =(H14-G14)/G14 -> 0.12 | I15: =(I14-H14)/H14 -> 0.1 | J15: =(J14-I14)/I14 -> 0.085 | K15: =(K14-J14)/J14 -> 0.065 | ... O15: =(O14-N14)/N14 -> 0.04
B16: Bruttomargin | C16: 0.522 | D16: 0.525 | E16: 0.477 | F16: =Antagelser!C62 -> 0.48 | G16: =Antagelser!D62 -> 0.5 | H16: =Antagelser!E62 -> 0.515 | I16: =Antagelser!F62 -> 0.525 | J16: =Antagelser!G62 -> 0.53 | K16: =Antagelser!H62 -> 0.53 | L16: =Antagelser!I62 -> 0.53 | M16: =Antagelser!J62 -> 0.53 | ... O16: =Antagelser!L62 -> 0.53
B17: Bruttobidrag | C17: =C16*C14 -> 140.9922 | D17: =D16*D14 -> 139.545 | E17: =E16*E14 -> 104.0814 | F17: =F16*F14 -> 101.59392 | G17: =G16*G14 -> 116.4097 | H17: =H16*H14 -> 134.29023 | I17: =I16*I14 -> 150.58759 | J17: =J16*J14 -> 164.9436 | ... O17: =O16*O14 -> 214.51914
B18: Driftskostnader | C18: 79.5 | D18: 79.4 | E18: 80.6 | F18: =E18*(1+Antagelser!C63) -> 74.958 | G18: =F18*(1+Antagelser!D63) -> 75.70758 | H18: =G18*(1+Antagelser!E63) -> 77.978807 | I18: =H18*(1+Antagelser!F63) -> 81.09796 | J18: =I18*(1+Antagelser!G63) -> 84.341878 | K18: =J18*(1+Antagelser!H63) -> 89.8241 | L18: =K18*(1+Antagelser!I63) -> 95.213546 | M18: =L18*(1+Antagelser!J63) -> 100.45029 | ... O18: =N18*(1+Antagelser!L63) -> 109.69172
B19: Justert EBITA | C19: =C17-C18 -> 61.4922 | D19: =D17-D18 -> 60.145 | E19: =E17-E18 -> 23.4814 | F19: =F17-F18 -> 26.63592 | G19: =G17-G18 -> 40.70212 | H19: =H17-H18 -> 56.311423 | I19: =I17-I18 -> 69.489628 | J19: =J17-J18 -> 80.601727 | ... O19: =O17-O18 -> 104.82742
B20: Justert EBITA-margin | C20: =C19/C14 -> 0.22766457 | D20: =D19/D14 -> 0.22627916 | E20: =E19/E14 -> 0.10761412 | F20: =F19/F14 -> 0.12584652 | G20: =G19/G14 -> 0.17482272 | H20: =H19/H14 -> 0.21595303 | I20: =I19/I14 -> 0.24226469 | J20: =J19/J14 -> 0.25899104 | ... O20: =O19/O14 -> 0.25899104
B22: FOOD
B23: Omsetning | C23: 319.6 | D23: 310.9 | E23: 328 | F23: =E23*(1+Antagelser!C66) -> 352.6 | G23: =F23*(1+Antagelser!D66) -> 380.808 | H23: =G23*(1+Antagelser!E66) -> 411.27264 | I23: =H23*(1+Antagelser!F66) -> 444.17445 | J23: =I23*(1+Antagelser!G66) -> 479.70841 | K23: =J23*(1+Antagelser!H66) -> 508.49091 | L23: =K23*(1+Antagelser!I66) -> 536.45791 | M23: =L23*(1+Antagelser!J66) -> 563.28081 | ... O23: =N23*(1+Antagelser!L66) -> 612.17358
B24: Vekst | D24: =(D23-C23)/C23 -> -0.027221527 | E24: =(E23-D23)/D23 -> 0.055001608 | F24: =(F23-E23)/E23 -> 0.075 | G24: =(G23-F23)/F23 -> 0.08 | H24: =(H23-G23)/G23 -> 0.08 | I24: =(I23-H23)/H23 -> 0.08 | J24: =(J23-I23)/I23 -> 0.08 | K24: =(K23-J23)/J23 -> 0.06 | ... O24: =(O23-N23)/N23 -> 0.04
B25: Bruttomargin | C25: 0.407 | D25: 0.429 | E25: 0.469 | F25: =Antagelser!C67 -> 0.44 | G25: =Antagelser!D67 -> 0.46 | H25: =Antagelser!E67 -> 0.46 | I25: =Antagelser!F67 -> 0.465 | J25: =Antagelser!G67 -> 0.465 | K25: =Antagelser!H67 -> 0.465 | L25: =Antagelser!I67 -> 0.465 | M25: =Antagelser!J67 -> 0.465 | ... O25: =Antagelser!L67 -> 0.465
B26: Bruttobidrag | C26: =C23*C25 -> 130.0772 | D26: =D23*D25 -> 133.3761 | E26: =E23*E25 -> 153.832 | F26: =F23*F25 -> 155.144 | G26: =G23*G25 -> 175.17168 | H26: =H23*H25 -> 189.18541 | I26: =I23*I25 -> 206.54112 | J26: =J23*J25 -> 223.06441 | ... O26: =O23*O25 -> 284.66072
B27: Driftskostnader | C27: 122.4 | D27: 112.6 | E27: 110.3 | F27: =E27*(1+Antagelser!C68) -> 114.712 | G27: =F27*(1+Antagelser!D68) -> 118.15336 | H27: =G27*(1+Antagelser!E68) -> 121.69796 | I27: =H27*(1+Antagelser!F68) -> 125.3489 | J27: =I27*(1+Antagelser!G68) -> 129.10937 | K27: =J27*(1+Antagelser!H68) -> 136.85593 | L27: =K27*(1+Antagelser!I68) -> 144.383 | M27: =L27*(1+Antagelser!J68) -> 151.60215 | ... O27: =N27*(1+Antagelser!L68) -> 164.76122
B28: Justert EBITA | C28: =C26-C27 -> 7.6772 | D28: =D26-D27 -> 20.7761 | E28: =E26-E27 -> 43.532 | F28: =F26-F27 -> 40.432 | G28: =G26-G27 -> 57.01832 | H28: =H26-H27 -> 67.487454 | I28: =I26-I27 -> 81.19222 | J28: =J26-J27 -> 93.955043 | ... O28: =O26-O27 -> 119.89949
B29: Justert EBITA-margin | C29: =C28/C23 -> 0.024021277 | D29: =D28/D23 -> 0.066825667 | E29: =E28/E23 -> 0.13271951 | F29: =F28/F23 -> 0.11466818 | G29: =G28/G23 -> 0.14972984 | H29: =H28/H23 -> 0.1640942 | I29: =I28/I23 -> 0.18279354 | J29: =J28/J23 -> 0.19585865 | ... O29: =O28/O23 -> 0.19585865
B31: HORIZON
B32: Omsetning | C32: 0.8 | D32: 7.4 | E32: 32.3 | F32: 48 | G32: =60*1.2 -> 72 | H32: =75*1.2 -> 90 | I32: =90*1.2 -> 108 | J32: =105*1.2 -> 126 | K32: ='Forecast Base'!K32*1.2 -> 141.6 | L32: ='Forecast Base'!L32*1.2 -> 156 | M32: ='Forecast Base'!M32*1.2 -> 169.2 | N32: ='Forecast Base'!N32*1.2 -> 181.2 | O32: ='Forecast Base'!O32*1.2 -> 192
B33: Vekst | D33: =(D32-C32)/C32 -> 8.25 | E33: =(E32-D32)/D32 -> 3.3648649 | F33: =(F32-E32)/E32 -> 0.48606811 | G33: =(G32-F32)/F32 -> 0.5 | H33: =(H32-G32)/G32 -> 0.25 | I33: =(I32-H32)/H32 -> 0.2 | J33: =(J32-I32)/I32 -> 0.16666667 | K33: =(K32-J32)/J32 -> 0.12380952 | ... O33: =(O32-N32)/N32 -> 0.059602649
B34: Bruttomargin | C34: -1.194 | D34: 0.501 | E34: 0.594 | F34: 0.6 | G34: 0.62 | H34: 0.64 | I34: 0.65 | J34: 0.655 | K34: 0.66 | L34: 0.665 | M34: 0.67 | N34: 0.67 | O34: 0.67
B35: Bruttobidrag | C35: =C34*C32 -> -0.9552 | D35: =D34*D32 -> 3.7074 | E35: =E34*E32 -> 19.1862 | F35: =F34*F32 -> 28.8 | G35: =G34*G32 -> 44.64 | H35: =H34*H32 -> 57.6 | I35: =I34*I32 -> 70.2 | J35: =J34*J32 -> 82.53 | ... O35: =O34*O32 -> 128.64
B36: Driftskostnader | C36: 7.2 | D36: 11.1 | E36: 23.9 | F36: 29 | G36: =34*1.1 -> 37.4 | H36: =40*1.1 -> 44 | I36: =48*1.1 -> 52.8 | J36: =52*1.1 -> 57.2 | K36: ='Forecast Base'!K36*1.1 -> 64.9 | L36: ='Forecast Base'!L36*1.1 -> 71.5 | M36: ='Forecast Base'!M36*1.1 -> 78.1 | N36: ='Forecast Base'!N36*1.1 -> 84.7 | O36: ='Forecast Base'!O36*1.1 -> 90.2
B37: EBITA | C37: =C35-C36 -> -8.1552 | D37: =D35-D36 -> -7.3926 | E37: =E35-E36 -> -4.7138 | F37: =F35-F36 -> -0.2 | G37: =G35-G36 -> 7.24 | H37: =H35-H36 -> 13.6 | I37: =I35-I36 -> 17.4 | J37: =J35-J36 -> 25.33 | ... O37: =O35-O36 -> 38.44
B38: EBITA-margin | C38: =C37/C32 -> -10.194 | D38: =D37/D32 -> -0.999 | E38: =E37/E32 -> -0.14593808 | F38: =F37/F32 -> -0.0041666667 | G38: =G37/G32 -> 0.10055556 | H38: =H37/H32 -> 0.15111111 | I38: =I37/I32 -> 0.16111111 | J38: =J37/J32 -> 0.20103175 | ... O38: =O37/O32 -> 0.20020833
B40: KONSERNFUNKSJONER | C40: -14.7 | D40: -22.7 | E40: -17 | F40: =(C40+D40+E40)/3 -> -18.133333 | G40: -18.7 | H40: -19.3 | I40: -19.9 | J40: -20.5 | K40: ='Forecast Base'!K40 -> -21.5 | L40: ='Forecast Base'!L40 -> -22.5 | M40: ='Forecast Base'!M40 -> -23.5 | N40: ='Forecast Base'!N40 -> -24.5 | O40: ='Forecast Base'!O40 -> -25.5
B41: EBITA | C41: =C10+C19+C28+C37+C40 -> 161.6768 | D41: =D10+D19+D28+D37+D40 -> 181.5071 | E41: =E10+E19+E28+E37+E40 -> 171.6881 | F41: =F10+F19+F28+F37+F40 -> 213.03254 | G41: =G10+G19+G28+G37+G40 -> 281.96724 | H41: =H10+H19+H28+H37+H40 -> 341.56437 | I41: =I10+I19+I28+I37+I40 -> 403.54553 | J41: =J10+J19+J28+J37+J40 -> 463.95789 | ... O41: =O10+O19+O28+O37+O40 -> 609.54822
B43: TOMRA GROUP
B44: Omsetning | C44: =C32+C23+C14+C5 -> 1287.9 | D44: =D32+D23+D14+D5 -> 1357.2 | E44: =E32+E23+E14+E5 -> 1319 | F44: =F32+F23+F14+F5 -> 1493.449 | G44: =G32+G23+G14+G5 -> 1646.13 | H44: =H32+H23+H14+H5 -> 1808.9781 | I44: =I32+I23+I14+I5 -> 1974.9463 | J44: =J32+J23+J14+J5 -> 2143.7362 | ... O44: =O32+O23+O14+O5 -> 2812.1427
B45: Vekst | D45: =(D44-C44)/C44 -> 0.053808526 | E45: =(E44-D44)/D44 -> -0.028146183 | F45: =(F44-E44)/E44 -> 0.13225853 | G45: =(G44-F44)/F44 -> 0.10223379 | H45: =(H44-G44)/G44 -> 0.098927911 | I45: =(I44-H44)/H44 -> 0.091746904 | J45: =(J44-I44)/I44 -> 0.08546555 | K45: =(K44-J44)/J44 -> 0.067337721 | ... O45: =(O44-N44)/N44 -> 0.044167133
B46: Bruttobidrag | C46: =C35+C26+C17+C8 -> 548.3768 | D46: =D35+D26+D17+D8 -> 590.5071 | E46: =E35+E26+E17+E8 -> 585.8881 | F46: =F35+F26+F17+F8 -> 646.82787 | G46: =G35+G26+G17+G8 -> 734.82994 | H46: =H35+H26+H17+H8 -> 815.55897 | I46: =I35+I26+I17+I8 -> 902.15093 | J46: =J35+J26+J17+J8 -> 983.34602 | ... O46: =O35+O26+O17+O8 -> 1297.9641
B47: Bruttomargin | C47: =C46/C44 -> 0.42579144 | D47: =D46/D44 -> 0.43509218 | E47: =E46/E44 -> 0.44419113 | F47: =F46/F44 -> 0.43311012 | G47: =G46/G44 -> 0.4463985 | H47: =H46/H44 -> 0.45083959 | I47: =I46/I44 -> 0.45679771 | J47: =J46/J44 -> 0.45870664 | ... O47: =O46/O44 -> 0.461557
...

Sheet DCF
B2: TOMRA ASA - DCF
B4: DCF
B5: Antall aksjer | C5: ='Historiske finansielle tall'!C5 -> 296040156
B6: EUR/NOK | C6: 10.92
B9: DCF Base
M10: Terminal
B11: EUR mill | C11: 2026E | D11: 2027E | E11: 2028E | F11: 2029E | G11: 2030E | H11: 2031E | I11: 2032E | J11: 2033E | K11: 2034E | L11: 2035E | M11: 2036E
B12: FCFF | C12: ='Forecast Base'!C63 -> 59.581253 | D12: ='Forecast Base'!D63 -> 116.88699 | E12: ='Forecast Base'!E63 -> 148.4165 | F12: ='Forecast Base'!F63 -> 179.7021 | G12: ='Forecast Base'!G63 -> 208.2105 | H12: ='Forecast Base'!H63 -> 218.89802 | I12: ='Forecast Base'!I63 -> 236.68222 | J12: ='Forecast Base'!J63 -> 248.37163 | ... L12: ='Forecast Base'!L63 -> 258.44688 | M12: =L12*(1+C14) -> 263.61582
B13: Periode | C13: 1 | D13: 2 | E13: 3 | F13: 4 | G13: 5 | H13: 6 | I13: 7 | J13: 8 | K13: 9 | L13: 10
B14: Terminalvekst | C14: 0.02
B15: WACC | C15: =WACC!C32 -> 0.08323486
B16: Diskonteringsfaktor | C16: =1/(1+$C$15)^C13 -> 0.92316084 | D16: =1/(1+$C$15)^D13 -> 0.85222593 | E16: =1/(1+$C$15)^E13 -> 0.7867416 | F16: =1/(1+$C$15)^F13 -> 0.72628904 | G16: =1/(1+$C$15)^G13 -> 0.6704816 | H16: =1/(1+$C$15)^H13 -> 0.61896235 | I16: =1/(1+$C$15)^I13 -> 0.5714018 | J16: =1/(1+$C$15)^J13 -> 0.52749577 | ... L16: =1/(1+$C$15)^L13 -> 0.44954557
B17: Nåverdi FCFF | C17: =C12*C16 -> 55.003079 | D17: =D12*D16 -> 99.614128 | E17: =E12*E16 -> 116.76544 | F17: =F12*F16 -> 130.51567 | G17: =G12*G16 -> 139.60131 | H17: =H12*H16 -> 135.48963 | I17: =I12*I16 -> 135.24065 | J17: =J12*J16 -> 131.01498 | ... L17: =L12*L16 -> 116.18365
B18: Terminalverdi | L18: =M12/(C15-C14) -> 4168.837
B19: Terminal nv | L19: =L18*L16 -> 1874.0822
B20: Enterprise value | C20: =C17+D17+E17+F17+G17+H17+I17+J17+L17+K17+L19 -> 3057.465
B21: Netto rentebærende gjeld | C21: =505+55-69 -> 491
B22: Leasinggjeld | C22: =105+44 -> 149
B23: Minoritetsinteresser | C23: 40
B24: Andre justeringer | C24: 0
B25: Egenkapitalverdi | C25: =C20-C21-C22-C23-C24 -> 2377.465
B27: Verdi per aksje | C27: =C25/(C5/1000000) -> 8.0308868
B28: Verdi per aksje i NOK | C28: =C27*C6 -> 87.697284
B33: DCF Bear
M34: Terminal
B35: EUR mill | C35: 2026E | D35: 2027E | E35: 2028E | F35: 2029E | G35: 2030E | H35: 2031E | I35: 2032E | J35: 2033E | K35: 2034E | L35: 2035E | M35: 2036E
B36: FCFF | C36: ='Forecast Bear'!C63 -> 30.923465 | D36: ='Forecast Bear'!D63 -> 80.663167 | E36: ='Forecast Bear'!E63 -> 96.361654 | F36: ='Forecast Bear'!F63 -> 116.62594 | G36: ='Forecast Bear'!G63 -> 132.33098 | H36: ='Forecast Bear'!H63 -> 127.2681 | I36: ='Forecast Bear'!I63 -> 144.05243 | J36: ='Forecast Bear'!J63 -> 157.05318 | ... L36: ='Forecast Bear'!L63 -> 171.20359 | M36: =L36*(1+C38) -> 174.62766
B37: Periode | C37: 1 | D37: 2 | E37: 3 | F37: 4 | G37: 5 | H37: 6 | I37: 7 | J37: 8 | K37: 9 | L37: 10
B38: Terminalvekst | C38: 0.02
B39: WACC | C39: =C15 -> 0.08323486
B40: Diskonteringsfaktor | C40: =1/(1+$C$39)^C37 -> 0.92316084 | D40: =1/(1+$C$39)^D37 -> 0.85222593 | E40: =1/(1+$C$39)^E37 -> 0.7867416 | F40: =1/(1+$C$39)^F37 -> 0.72628904 | G40: =1/(1+$C$39)^G37 -> 0.6704816 | H40: =1/(1+$C$39)^H37 -> 0.61896235 | I40: =1/(1+$C$39)^I37 -> 0.5714018 | J40: =1/(1+$C$39)^J37 -> 0.52749577 | ... L40: =1/(1+$C$39)^L37 -> 0.44954557
B41: Nåverdi FCFF | C41: =C36*C40 -> 28.547332 | D41: =D36*D40 -> 68.743242 | E41: =E36*E40 -> 75.811723 | F41: =F36*F40 -> 84.704145 | G41: =G36*G40 -> 88.725484 | H41: =H36*H40 -> 78.774164 | I41: =I36*I40 -> 82.311817 | J41: =J36*J40 -> 82.844889 | ... L41: =L36*L40 -> 76.963816
B42: Terminalverdi | L42: =M36/(C39-C38) -> 2761.5727
B43: Terminal nv | L43: =L42*L40 -> 1241.4528
B44: Enterprise value | C44: =C41+D41+E41+F41+G41+H41+I41+J41+K41+L41+L43 -> 1988.1083
B45: Netto rentebærende gjeld | C45: =505+55-69 -> 491
B46: Leasinggjeld | C46: =105+44 -> 149
B47: Minoritetsinteresser | C47: 40
B48: Andre justeringer | C48: 0
B49: Egenkapitalverdi | C49: =C44-C45-C46-C47-C48 -> 1308.1083
...

Sheet Reverse DCF
B2: TOMRA ASA - Reverse DCF
B4: Dagens aksjekurs | C4: ='Historiske finansielle tall'!C4 -> 104.8
B5: Base DCF-verdi | C5: =DCF!C28 -> 87.697284
B6: WACC | C6: =WACC!C32 -> 0.08323486
B7: Terminalvekst | C7: 0.02
B8: Forskjell mot markedskurs | C8: =C4-C5 -> 17.102716
B10: Marginpåslag 2035, pp | C10: 0.024712185
B12: Reverse DCF basert på EBITA-margin
C13: ='Forecast Base'!E4 -> 2025 | D13: ='Forecast Base'!F4 -> 2026E | E13: ='Forecast Base'!G4 -> 2027E | F13: ='Forecast Base'!H4 -> 2028E | G13: ='Forecast Base'!I4 -> 2029E | H13: ='Forecast Base'!J4 -> 2030E | I13: ='Forecast Base'!K4 -> 2031E | J13: ='Forecast Base'!L4 -> 2032E | ... M13: ='Forecast Base'!O4 -> 2035E
B14: Base EBITA-margin | C14: ='Forecast Base'!E49 -> 0.13016535 | D14: ='Forecast Base'!F49 -> 0.13015619 | E14: ='Forecast Base'!G49 -> 0.1502628 | F14: ='Forecast Base'!H49 -> 0.16236099 | G14: ='Forecast Base'!I49 -> 0.16882573 | H14: ='Forecast Base'!J49 -> 0.17587806 | I14: ='Forecast Base'!K49 -> 0.17789446 | J14: ='Forecast Base'!L49 -> 0.17920995 | ... M14: ='Forecast Base'!O49 -> 0.17690804
B15: Innfasing | D15: 0.1 | E15: 0.2 | F15: 0.3 | G15: 0.4 | H15: 0.5 | I15: 0.6 | J15: 0.7 | K15: 0.8 | L15: 0.9 | M15: 1
B16: Implisitt EBITA-margin | C16: =C14+$C$10*C15 -> 0.13016535 | D16: =D14+$C$10*D15 -> 0.13262741 | E16: =E14+$C$10*E15 -> 0.15520524 | F16: =F14+$C$10*F15 -> 0.16977465 | G16: =G14+$C$10*G15 -> 0.1787106 | H16: =H14+$C$10*H15 -> 0.18823416 | I16: =I14+$C$10*I15 -> 0.19272177 | J16: =J14+$C$10*J15 -> 0.19650848 | ... M16: =M14+$C$10*M15 -> 0.20162023
C19: =D13 -> 2026E | D19: =E13 -> 2027E | E19: =F13 -> 2028E | F19: =G13 -> 2029E | G19: =H13 -> 2030E | H19: =I13 -> 2031E | I19: =J13 -> 2032E | J19: =K13 -> 2033E | ... L19: =M13 -> 2035E
B20: Base omsetning | C20: ='Forecast Base'!F44 -> 1480.04 | D20: ='Forecast Base'!G44 -> 1603.0936 | E20: ='Forecast Base'!H44 -> 1732.8263 | F20: ='Forecast Base'!I44 -> 1854.2302 | G20: ='Forecast Base'!J44 -> 1977.7436 | H20: ='Forecast Base'!K44 -> 2092.6105 | I20: ='Forecast Base'!L44 -> 2203.341 | J20: ='Forecast Base'!M44 -> 2307.6414 | ... L20: ='Forecast Base'!O44 -> 2486.0392
B21: Implisitt EBITA-margin | C21: =D16 -> 0.13262741 | D21: =E16 -> 0.15520524 | E21: =F16 -> 0.16977465 | F21: =G16 -> 0.1787106 | G21: =H16 -> 0.18823416 | H21: =I16 -> 0.19272177 | I21: =J16 -> 0.19650848 | J21: =K16 -> 0.19924681 | ... L21: =M16 -> 0.20162023
B22: Implisitt EBITA | C22: =C20*C21 -> 196.29387 | D22: =D20*D21 -> 248.80852 | E22: =E20*E21 -> 294.18998 | F22: =F20*F21 -> 331.3706 | G22: =G20*G21 -> 372.2789 | H22: =H20*H21 -> 403.29161 | I22: =I20*I21 -> 432.9752 | J22: =J20*J21 -> 459.79018 | ... L22: =L20*L21 -> 501.23578
B25: Implisitt EBITA | C25: =C22 -> 196.29387 | D25: =D22 -> 248.80852 | E25: =E22 -> 294.18998 | F25: =F22 -> 331.3706 | G25: =G22 -> 372.2789 | H25: =H22 -> 403.29161 | I25: =I22 -> 432.9752 | J25: =J22 -> 459.79018 | ... L25: =L22 -> 501.23578
B26: Amortisering | C26: ='Forecast Base'!C55 -> 29.6008 | D26: ='Forecast Base'!D55 -> 30.458778 | E26: ='Forecast Base'!E55 -> 31.190874 | F26: ='Forecast Base'!F55 -> 31.521914 | G26: ='Forecast Base'!G55 -> 33.621642 | H26: ='Forecast Base'!H55 -> 33.481768 | I26: ='Forecast Base'!I55 -> 33.050116 | J26: ='Forecast Base'!J55 -> 32.306979 | ... L26: ='Forecast Base'!L55 -> 29.83247
B27: Implisitt EBIT | C27: =C25-C26 -> 166.69307 | D27: =D25-D26 -> 218.34974 | E27: =E25-E26 -> 262.9991 | F27: =F25-F26 -> 299.84868 | G27: =G25-G26 -> 338.65726 | H27: =H25-H26 -> 369.80984 | I27: =I25-I26 -> 399.92509 | J27: =J25-J26 -> 427.4832 | ... L27: =L25-L26 -> 471.40331
B28: Skatt | C28: 0.245 | D28: 0.245 | E28: 0.245 | F28: 0.245 | G28: 0.245 | H28: 0.245 | I28: 0.245 | J28: 0.245 | K28: 0.245 | L28: 0.245
B29: Implisitt NOPAT | C29: =C27*(1-C28) -> 125.85327 | D29: =D27*(1-D28) -> 164.85406 | E29: =E27*(1-E28) -> 198.56432 | F29: =F27*(1-F28) -> 226.38576 | G29: =G27*(1-G28) -> 255.68623 | H29: =H27*(1-H28) -> 279.20643 | I29: =I27*(1-I28) -> 301.94344 | J29: =J27*(1-J28) -> 322.74982 | ... L29: =L27*(1-L28) -> 355.9095
B30: D&A | C30: ='Forecast Base'!C59 -> 125.8034 | D30: ='Forecast Base'!D59 -> 133.05677 | E30: ='Forecast Base'!E59 -> 138.62611 | F30: ='Forecast Base'!F59 -> 144.62996 | G30: ='Forecast Base'!G59 -> 148.33077 | H30: ='Forecast Base'!H59 -> 152.76057 | I30: ='Forecast Base'!I59 -> 156.43721 | J30: ='Forecast Base'!J59 -> 159.22726 | ... L30: ='Forecast Base'!L59 -> 161.59255
B31: Capex | C31: ='Forecast Base'!C60 -> 148.004 | D31: ='Forecast Base'!D60 -> 152.29389 | E31: ='Forecast Base'!E60 -> 155.95437 | F31: ='Forecast Base'!F60 -> 157.60957 | G31: ='Forecast Base'!G60 -> 158.21949 | H31: ='Forecast Base'!H60 -> 163.22362 | I31: ='Forecast Base'!I60 -> 171.8606 | J31: ='Forecast Base'!J60 -> 179.99603 | ... L31: ='Forecast Base'!L60 -> 193.91106
B32: Endring i arbeidskapital | C32: ='Forecast Base'!C62 -> 41.31 | D32: ='Forecast Base'!D62 -> 22.747932 | E32: ='Forecast Base'!E62 -> 23.120392 | F32: ='Forecast Base'!F62 -> 19.865776 | G32: ='Forecast Base'!G62 -> 19.136937 | H32: ='Forecast Base'!H62 -> 26.419382 | I32: ='Forecast Base'!I62 -> 21.061339 | J32: ='Forecast Base'!J62 -> 19.165196 | ... L32: ='Forecast Base'!L62 -> 18.760338
B33: Implisitt FCFF | C33: =C29+C30-C31-C32 -> 62.342667 | D33: =D29+D30-D31-D32 -> 122.869 | E33: =E29+E30-E31-E32 -> 158.11567 | F33: =F29+F30-F31-F32 -> 193.54037 | G33: =G29+G30-G31-G32 -> 226.66058 | H33: =H29+H30-H31-H32 -> 242.324 | I33: =I29+I30-I31-I32 -> 265.45871 | J33: =J29+J30-J31-J32 -> 282.81585 | ... L33: =L29+L30-L31-L32 -> 304.83065
B37: EUR mill | C37: 2026E | D37: 2027E | E37: 2028E | F37: 2029E | G37: 2030E | H37: 2031E | I37: 2032E | J37: 2033E | K37: 2034E | L37: 2035E | M37: 2036E
B38: Implisitt FCFF | C38: =C33 -> 62.342667 | D38: =D33 -> 122.869 | E38: =E33 -> 158.11567 | F38: =F33 -> 193.54037 | G38: =G33 -> 226.66058 | H38: =H33 -> 242.324 | I38: =I33 -> 265.45871 | J38: =J33 -> 282.81585 | ... L38: =L33 -> 304.83065 | M38: =L38*(1+C40) -> 310.92727
B39: Periode | C39: 1 | D39: 2 | E39: 3 | F39: 4 | G39: 5 | H39: 6 | I39: 7 | J39: 8 | K39: 9 | L39: 10
B40: Terminalvekst | C40: 0.02
B41: WACC | C41: =C6 -> 0.08323486
B42: Diskonteringsfaktor | C42: =1/(1+$C$41)^C39 -> 0.92316084 | D42: =1/(1+$C$41)^D39 -> 0.85222593 | E42: =1/(1+$C$41)^E39 -> 0.7867416 | F42: =1/(1+$C$41)^F39 -> 0.72628904 | G42: =1/(1+$C$41)^G39 -> 0.6704816 | H42: =1/(1+$C$41)^H39 -> 0.61896235 | I42: =1/(1+$C$41)^I39 -> 0.5714018 | J42: =1/(1+$C$41)^J39 -> 0.52749577 | ... L42: =1/(1+$C$41)^L39 -> 0.44954557
B43: Nåverdi FCFF | C43: =C38*C42 -> 57.552309 | D43: =D38*D42 -> 104.71215 | E43: =E38*E42 -> 124.39617 | F43: =F38*F42 -> 140.56625 | G43: =G38*G42 -> 151.97175 | H43: =H38*H42 -> 149.98943 | I43: =I38*I42 -> 151.68359 | J43: =J38*J42 -> 149.18416 | ... L43: =L38*L42 -> 137.03527
B44: Terminalverdi | L44: =M38/(C41-C40) -> 4917.0231
B45: Terminal nv | L45: =L44*L42 -> 2210.426
B46: Enterprise value | C46: =C43+D43+E43+F43+G43+H43+I43+J43+K43+L43+L45 -> 3521.118
B47: Netto rentebærende gjeld | C47: =505+55-69 -> 491
B48: Leasinggjjeld | C48: =105+44 -> 149
B49: Minoritetsinteresser | C49: 40
B50: Andre justeringer | C50: 0
B51: Egenkapitalverdi | C51: =C46-C47-C48-C49-C50 -> 2841.118
...

Sheet Peer Analyse
B2: TOMRA - Peer Analyse
B3: Brukt som et suplement til DCF - ikke hovedverdsettelsen
B5: EV, MEUR | C5: =('Historiske finansielle tall'!C4*('Historiske finansielle tall'!C5/1000000))/DCF!C6+DCF!C21+DCF!C22+DCF!C23 -> 3521.118
B7: Selskap | C7: Tomra-segment | D7: Relevans
B8: Envipco | C8: Collection | D8: Direkte RVM-konkurrent
B9: JBT Marel | C9: Food | D9: Matprosessering og automasjon
B10: GEA Group | C10: Food | D10: Prosessutstyr for mat og drikke
B11: Krones | C11: Recycling/emballasje | D11: PET-, emballasje og resirkuleringssystemer
B12: ANDRITZ | C12: Recycling | D12: Industrielt prosess- og resirkuleringsutstyr
B17: Trading comps -2027E | D17: 2026E | H17: 2027E
B18: Selskap | C18: Gruppe | D18: Salgsvekst | E18: EBIT-margin | F18: EV/Sales | G18: EV/EBIT | H18: Salgsvekst | I18: EBIT-margin | J18: EV/sales | K18: EV/EBIT | L18: P/E
B19: TOMRA (markedskonsensus) | C19: TOMRA | D19: =(1498-1318)/1318 -> 0.13657056 | E19: =165.3/1498 -> 0.11034713 | F19: 2.24 | G19: 20.4 | H19: =(1784-1498)/1498 -> 0.19092123 | I19: =273.1/1784 -> 0.15308296 | J19: =1.84 -> 1.84 | K19: 12 | L19: 14.5 | N19: Kilde: https://www.marketscreener.com/quote/stock/TOMRA-SYSTEMS-ASA-438799/valuation/
B20: TOMRA (egne estimater) | C20: TOMRA | D20: ='Forecast Base'!F45 -> 0.12209249 | E20: ='Forecast Base'!C56/'Forecast Base'!C52 -> 0.11015619 | F20: =C5/'Forecast Base'!F44 -> 2.3790695 | G20: =C5/'Forecast Base'!C56 -> 21.597238 | H20: ='Forecast Base'!G45 -> 0.083142077 | I20: ='Forecast Base'!D56/'Forecast Base'!D52 -> 0.1312628 | J20: =C5/'Forecast Base'!G44 -> 2.1964519 | K20: =C5/'Forecast Base'!D56 -> 16.73324
B21: Envipco | C21: Direkte Collection- peer | D21: =(123.6-90.35)/90.35 -> 0.36801328 | E21: =0.7215/123.6 -> 0.0058373786 | F21: 1.93 | G21: 330 | H21: =(267.6-123.6)/123.6 -> 1.1650485 | I21: =54.12/267.6 -> 0.20224215 | J21: 0.99 | K21: 4.91 | L21: 5.04 | N21: Kilde: https://www.marketscreener.com/quote/stock/ENVIPCO-HOLDING-N-V-46512764/valuation/
